<!-- =========================================================================== #
# Title:          XML Model File for a 2DOF Slider Robot
# Author:         Moses C. Nah
# Creation Date:  Monday, Feb. 26st, 2024
# =========================================================================== -->

<mujoco model="2DOF_slider">

  <compiler angle = "radian" />
  <option  timestep  = '0.0001' iterations = '50' integrator = 'Euler' gravity = "0 0 0" collision = 'all' />
  <asset>
     <texture type = "skybox" builtin = "flat" rgb1 = "1 1 1" width	= "200" height = "200"/>
  </asset>

  <worldbody>
    <body name='slider' pos='0 0 0' euler='0 0 0'>
        <joint name='joint1' ref='0' type='slide' stiffness='0' pos='0 0 0' axis='1 0 0' />
        <joint name='joint2' ref='0' type='slide' stiffness='0' pos='0 0 0' axis='0 1 0' />
        <geom name='geom1' type='sphere' pos='0 0 0' size='0.1' mass='1'/>
        <site name='site1' pos='0 0 0' />
        <body name='hanger' pos='0 0 0' euler='0 0 0'>
            <site name='forForceSensorSite' pos='0 0 0' />
            <joint name='joint3' ref='0' type='hinge' damping='0.0' stiffness='0' pos='0 0 0' axis='0 0 1' />
            <geom type='cylinder' fromto='0 0 0 2 0 0'   size='0.04' mass='0'/>
            <geom name='geom2' type='sphere' pos='2 0 0' size='0.1' mass='1'/>
            <site name='site2' pos='2 0 0' />
        </body>
    </body>
  </worldbody>

    <sensor>
        <force name = 'wristForceSensorSite' site = 'forForceSensorSite' />
    </sensor>

	<actuator>
		<motor joint = 'joint1' name = 'sliderjoint1' forcelimited = 'false' />
		<motor joint = 'joint2' name = 'sliderjoint2' forcelimited = 'false' />
    </actuator>

</mujoco>