<mujoco model="5DOF_snakebot">

  <!-- Setting 'inertiafromgeom' as 'auto' forces the MuJoCo compiler to infer the inertial attributes based on defined geom + mass value, and will only use the inertia values if it is specifically defined.
       By setting 'inertiafromgeom' as 'auto', the xml compiler will use the explicitly defined inertial parameters for the upperArm and foreArm body,
       and will infer the inertial parameters from geometry for the whip model -->
  <compiler inertiafromgeom = "auto" angle = "radian"/>

   <!-- (semi-) implicit Euler method was used for the integrator with time step of 0.1ms -->
	<option timestep='0.0001' iterations='50' integrator='Euler' collision='all' gravity="0 0 -9.81"/>

  <asset>
    <!-- Texture of the surrounding sky box
         setting everything as white-ish color for better visualization -->
     <texture type="skybox"
              builtin="flat"
              rgb1="1 1 1"
              rgb2="1 1 1"
              width="100"
              height="100"/>

        <material name="blue"  rgba="0 0 1 1" />
        <material name="green" rgba="0 1 0 1" />
        <material name="red"   rgba="1 0 0 1" />
        <material name="white" rgba="1 1 1 1" />
        <material name="grey"  rgba=".4 .4 .4 1" />


  </asset>

  <worldbody>

    <body name='camera' pos='0 0 0'>
		  <camera name='myCamera' pos='0.7975 -3.19 -0.4785' euler='1.5707 0 0'/>
  	</body>

		<body name='body_link1' pos='0 0 0' euler='0 0 0'>
      <joint name='joint_1' ref='0' type='hinge' stiffness='0' pos='0 0 0' axis='0 -1 0' />
			<inertial pos='0 0 -0.5' mass='1' diaginertia='1.0 1.0 1.0'/>
      <site pos='0 0 -0.5' name='site_COM1' />
			<geom name='geom_joint1' type='sphere' pos='0 0 0' material='grey' size='0.2' mass='0'/>
			<geom type='cylinder' fromto='0 0 0 0 0 -1' material='grey' size='0.1' mass='0'/>

			<body name='body_link2' pos='0 0 -1' euler='0 0 0'>
        <joint name='joint_2' ref='0' type='hinge' stiffness='0' pos='0 0 0' axis='0 -1 0'/>
				<inertial pos='0 0 -0.5' mass='1.0' diaginertia='1.0 1.0 1.0'/>
        <site pos='0 0 -0.5' name='site_COM2' />
				<geom name='geom_joint2'       type='sphere' pos='0 0 0' material='grey'  size='0.2' mass='0'/>
				<geom type='cylinder' fromto='0 0 0 0 0 -1.0'  material='grey'  size='0.1' mass='0'/>

        <body name='body_link3' pos='0 0 -1' euler='0 0 0'>
          <joint name='joint_3' ref='0' type='hinge' stiffness='0' pos='0 0 0' axis='0 -1 0'/>
          <inertial pos='0 0 -0.5' mass='1.0' diaginertia='1.0 1.0 1.0'/>
          <site pos='0 0 -0.5' name='site_COM3' />
          <geom name='geom_joint3'       type='sphere' pos='0 0 0' material='grey'  size='0.2' mass='0'/>
          <geom type='cylinder' fromto='0 0 0 0 0 -1.0'  material='grey'  size='0.1' mass='0'/>

          <body name='body_link4' pos='0 0 -1' euler='0 0 0'>
            <joint name='joint_4' ref='0' type='hinge' stiffness='0' pos='0 0 0' axis='0 -1 0'/>
            <inertial pos='0 0 -0.5' mass='1.0' diaginertia='1.0 1.0 1.0'/>
            <site pos='0 0 -0.5' name='site_COM4' />
            <geom name='geom_joint4'       type='sphere' pos='0 0 0' material='grey'  size='0.2' mass='0'/>
            <geom type='cylinder' fromto='0 0 0 0 0 -1.0'  material='grey'  size='0.1' mass='0'/>

            <body name='body_link5' pos='0 0 -1' euler='0 0 0'>
              <joint name='joint_5' ref='0' type='hinge' stiffness='0' pos='0 0 0' axis='0 -1 0'/>
              <inertial pos='0 0 -0.5' mass='1.0' diaginertia='1.0 1.0 1.0'/>
              <site pos='0 0 -0.5' name='site_COM5' />
              <geom name='geom_joint5'       type='sphere' pos='0 0 0' material='grey'  size='0.2' mass='0'/>
              <geom type='cylinder' fromto='0 0 0 0 0 -1.0'  material='grey'  size='0.1' mass='0'/>
				      <geom name='geom_EE' type='sphere' pos='0 0 -1.0' material='grey' size='0.2' mass='0'/>
            </body>
          </body>
        </body> 
      </body>
  </body>

  </worldbody>

  <actuator>
		  <motor joint='joint_1' name='motor_joint_1' forcelimited='false'/>
		  <motor joint='joint_2' name='motor_joint_2' forcelimited='false'/>
      <motor joint='joint_3' name='motor_joint_3' forcelimited='false'/>
      <motor joint='joint_4' name='motor_joint_4' forcelimited='false'/>
      <motor joint='joint_5' name='motor_joint_5' forcelimited='false'/>
  </actuator>

</mujoco>